{"remainingRequest":"/Users/jpregelj/eots/frontend/node_modules/@angular-devkit/build-optimizer/src/build-optimizer/webpack-loader.js??ref--3-1!/Users/jpregelj/eots/frontend/node_modules/rxjs/_esm5/operators/catchError.js","dependencies":[{"path":"/Users/jpregelj/eots/frontend/node_modules/rxjs/_esm5/operators/catchError.js","mtime":1513892921000},{"path":"/Users/jpregelj/eots/frontend/node_modules/cache-loader/dist/cjs.js","mtime":1510929699000},{"path":"/Users/jpregelj/eots/frontend/node_modules/@angular-devkit/build-optimizer/src/build-optimizer/webpack-loader.js","mtime":1519266497000}],"contextDependencies":[],"result":["import { __extends } from \"tslib\";\nimport { OuterSubscriber } from '../OuterSubscriber';\nimport { subscribeToResult } from '../util/subscribeToResult';\n/**\n * Catches errors on the observable to be handled by returning a new observable or throwing an error.\n *\n * <img src=\"./img/catch.png\" width=\"100%\">\n *\n * @example <caption>Continues with a different Observable when there's an error</caption>\n *\n * Observable.of(1, 2, 3, 4, 5)\n *   .map(n => {\n * \t   if (n == 4) {\n * \t     throw 'four!';\n *     }\n *\t   return n;\n *   })\n *   .catch(err => Observable.of('I', 'II', 'III', 'IV', 'V'))\n *   .subscribe(x => console.log(x));\n *   // 1, 2, 3, I, II, III, IV, V\n *\n * @example <caption>Retries the caught source Observable again in case of error, similar to retry() operator</caption>\n *\n * Observable.of(1, 2, 3, 4, 5)\n *   .map(n => {\n * \t   if (n === 4) {\n * \t     throw 'four!';\n *     }\n * \t   return n;\n *   })\n *   .catch((err, caught) => caught)\n *   .take(30)\n *   .subscribe(x => console.log(x));\n *   // 1, 2, 3, 1, 2, 3, ...\n *\n * @example <caption>Throws a new error when the source Observable throws an error</caption>\n *\n * Observable.of(1, 2, 3, 4, 5)\n *   .map(n => {\n *     if (n == 4) {\n *       throw 'four!';\n *     }\n *     return n;\n *   })\n *   .catch(err => {\n *     throw 'error in source. Details: ' + err;\n *   })\n *   .subscribe(\n *     x => console.log(x),\n *     err => console.log(err)\n *   );\n *   // 1, 2, 3, error in source. Details: four!\n *\n * @param {function} selector a function that takes as arguments `err`, which is the error, and `caught`, which\n *  is the source observable, in case you'd like to \"retry\" that observable by returning it again. Whatever observable\n *  is returned by the `selector` will be used to continue the observable chain.\n * @return {Observable} An observable that originates from either the source or the observable returned by the\n *  catch `selector` function.\n * @name catchError\n */\nexport function catchError(selector) {\n    return function catchErrorOperatorFunction(source) {\n        var operator = new CatchOperator(selector);\n        var caught = source.lift(operator);\n        return (operator.caught = caught);\n    };\n}\nvar CatchOperator = /*@__PURE__*/ (function () {\n    function CatchOperator(selector) {\n        this.selector = selector;\n    }\n    CatchOperator.prototype.call = function (subscriber, source) {\n        return source.subscribe(new CatchSubscriber(subscriber, this.selector, this.caught));\n    };\n    return CatchOperator;\n}());\n/**\n * We need this JSDoc comment for affecting ESDoc.\n * @ignore\n * @extends {Ignored}\n */\nvar CatchSubscriber = /*@__PURE__*/ (function (_super) {\n    __extends(CatchSubscriber, _super);\n    function CatchSubscriber(destination, selector, caught) {\n        _super.call(this, destination);\n        this.selector = selector;\n        this.caught = caught;\n    }\n    // NOTE: overriding `error` instead of `_error` because we don't want\n    // to have this flag this subscriber as `isStopped`. We can mimic the\n    // behavior of the RetrySubscriber (from the `retry` operator), where\n    // we unsubscribe from our source chain, reset our Subscriber flags,\n    // then subscribe to the selector result.\n    CatchSubscriber.prototype.error = function (err) {\n        if (!this.isStopped) {\n            var result = void 0;\n            try {\n                result = this.selector(err, this.caught);\n            }\n            catch (err2) {\n                _super.prototype.error.call(this, err2);\n                return;\n            }\n            this._unsubscribeAndRecycle();\n            this.add(subscribeToResult(this, result));\n        }\n    };\n    return CatchSubscriber;\n}(OuterSubscriber));\n//# sourceMappingURL=catchError.js.map \n",null]}